<?xml version="1.0"?>
<robot name="rov_max" xmlns:xacro="http://www.ros.org/wiki/xacro">

  <!-- ***************************** -->
  <!-- ********* PROPERTIES ******** -->
  <!-- ***************************** -->
  <xacro:property name="negligible" value="1e-5" />
  <xacro:property name="blade_geometry" value="0.015 0.02 .003" />

  <!-- ***************************** -->
  <!-- ********* MATERIALS ********* -->
  <!-- ***************************** -->
  <material name="LightBlue">
    <color rgba="0.678431 0.847059 0.901961 1.0"/>
  </material>

  <material name="MediumBlue">
    <color rgba="0.000000 0.000000 0.803922 1.0"/>
  </material>

  <material name="LightYellow">
    <color rgba="1.000000 1.000000 0.690196 1.0"/>
  </material>

  <material name="MediumYellow">
    <color rgba="1.000000 1.000000 0.000000 1.0"/>
  </material>

  <material name="Gray">
    <color rgba="0.7 0.7 0.7 1.0"/>
  </material>

  <material name="Black">
    <color rgba="0 0 0 1"/>
  </material>

  <material name="LightGreen">
    <color rgba="0.678431 1.000000 0.184314 1.0"/>
  </material>

  <material name="MediumGreen">
    <color rgba="0.000000 0.501961 0.000000 1.0"/>
  </material>

  <material name="Green">
    <color rgba="0.0 0.8 0.0 1.0"/>
  </material>

  <link name="rov_max_frame">
  </link>

  <!-- ***************************** -->
  <!-- ********* CHASSIS *********** -->
  <!-- ***************************** -->
  <link name="rov_max_shell">

    <visual>
      <!--The origin shift visually shifts the model to CAD model origin-->
      <origin xyz="0.15571 0.00016 0.00084" rpy="${pi} ${pi} 0" />
      <geometry>
        <mesh filename="package://rov_gazebo/models/rov_max/meshes/rov_max.stl" scale="0.001 0.001 0.001"/>
      </geometry>
      <material name="MediumYellow"/>
    </visual>

    <collision>
      <origin xyz="0.15571 0.00016 0.00084" rpy="${pi} ${pi} 0" />
      <geometry>
	      <!--Bounding box for collision geometry used to decrease computational requirements.-->
        <box size="0.53 0.32 0.033"/>
      </geometry>
    </collision>

    <inertial>
      <origin xyz="0.15571 0.00016 0.00084" rpy="${pi} ${pi} 0" />  
      <mass value="4.488"/>
      <inertia ixx=".03870488600000001" ixy="0.0" ixz="0.0" iyy=".067961036" iyz="0.0" izz=".10585135000000001"/>
    </inertial>

  </link>

  <joint name="base_frame_to_shell" type="fixed">
    <parent link="rov_max_frame"/>
    <child link="rov_max_shell"/>
    <origin xyz="0.15571 0.00016 0.00084" rpy="${pi} ${pi} 0"/>
    <axis xyz="0 0 1"/>
  </joint>

  <!-- ***************************** -->
  <!-- *********** CAMERA ********** -->
  <!-- ***************************** -->
  <link name="camera">
    <visual>
      <geometry>
        <box size="0.02 0.04 0.02"/>
      </geometry>
      <material name="Gray"/>
    </visual>

    <inertial>
      <mass value="0.00133"/>
      <inertia ixx="0.001" ixy="0.00" ixz="0.00" iyy="0.001" iyz="0.00" izz="0.001"/>
    </inertial>

  </link>

  <joint name="shell_to_camera" type="fixed">
    <parent link="rov_max_shell"/>
    <child link="camera"/>
    <origin xyz="0.15571 0 0"/>
    <axis xyz="0 0 1"/>
  </joint>

  <!-- ***************************** -->
  <!-- ********** SONAR ************ -->
  <!-- ***************************** -->
  <link name="sonar_link">
    <visual>
      <geometry>
        <box size="0.01 0.02 0.01"/>
      </geometry>
      <material name="Gray"/>
    </visual>

    <inertial>
      <mass value="0.002667"/>
      <inertia ixx="0.001" ixy="0.00" ixz="0.00" iyy="0.001" iyz="0.00" izz="0.001"/>
    </inertial>

  </link>

  <joint name="shell_to_sonar" type="fixed">
    <parent link="rov_max_shell"/>
    <child link="sonar_link"/>
    <origin xyz="0.075 0 0.05"/>
    <axis xyz="0 0 1"/>
  </joint>


  <!-- ***************************** -->
  <!-- **** VERTICAL THRUST LEFT *** -->
  <!-- ***************************** -->
  <link name="vert_thrust_left">
    <origin xyz="0 0 0" rpy="0 0 0"/>

    <inertial>
      <mass value="0.001"/>
      <inertia ixx="0.001" ixy="0.00" ixz="0.00" iyy="0.001" iyz="0.00" izz="0.001"/>
    </inertial>

    <visual>
      <origin xyz="0 0 0" rpy="${-pi/2} 0 0"/>
      <geometry>
        <mesh filename="package://rov_gazebo/models/rov_max/meshes/t200-ccw-prop.dae" scale="0.8 0.8 0.8"/>
      </geometry>
      <material name="Green"/>
    </visual>

  </link>

  <joint name="shell_to_vert_thrust_left" type="continuous">
    <parent link="rov_max_shell"/>
    <child link="vert_thrust_left"/>
    <axis xyz="0 0 1"/>
    <origin xyz="0.108 0.071 0" rpy="0 0 0"/>
  </joint>

  <!-- ***************************** -->
  <!-- *** VERTICAL THRUST RIGHT *** -->
  <!-- ***************************** -->
  <link name="vert_thrust_right">
    <origin xyz="0 0 0" rpy="0 0 0"/>

    <inertial>
      <mass value="0.001"/>
      <inertia ixx="0.001" ixy="0.00" ixz="0.00" iyy="0.001" iyz="0.00" izz="0.001"/>
    </inertial>

    <visual>
      <origin xyz="0 0 0" rpy="${pi/2} 0 0"/>
      <geometry>
        <mesh filename="package://rov_gazebo/models/rov_max/meshes/t200-cw-prop.dae" scale="0.8 0.8 0.8"/>
      </geometry>
      <material name="Green"/>
    </visual>

  </link>

  <joint name="shell_to_vert_thrust_right" type="continuous">
    <parent link="rov_max_shell"/>
    <child link="vert_thrust_right"/>
    <axis xyz="0 0 1"/>
    <origin xyz="0.108 -0.071 0"/>
  </joint>

  <!-- ***************************** -->
  <!-- ******* THRUSTER LEFT ******* -->
  <!-- ***************************** -->
  
  <link name="left_thruster">
    <origin xyz="0 0 0" rpy="0 0 0"/>

    <inertial>
      <mass value="0.001"/>
      <inertia ixx="0.001" ixy="0.00" ixz="0.00" iyy="0.001" iyz="0.00" izz="0.001"/>
    </inertial>

    <visual>
      <origin xyz="0 0 0" rpy="${-pi/2} 0 0"/>
      <geometry>
        <mesh filename="package://rov_gazebo/models/rov_max/meshes/t200-ccw-prop.dae" scale="0.8 0.8 0.8"/>
      </geometry>
      <material name="Green"/>
    </visual>

  </link>

  <joint name="shell_to_left_thrust" type="continuous">
    <parent link="rov_max_shell"/>
    <child link="left_thruster"/>
    <axis xyz="0 0 1"/>
    <origin xyz="-0.12429 0.075 0" rpy="0 ${pi/2} 0"/>
  </joint>

  <!-- ***************************** -->
  <!-- ******* THRUSTER RIGHT ****** -->
  <!-- ***************************** -->
  <link name="right_thruster">
    <origin xyz="0 0 0" rpy="0 0 0"/>

    <inertial>
      <mass value="0.001"/>
      <inertia ixx="0.001" ixy="0.00" ixz="0.00" iyy="0.001" iyz="0.00" izz="0.001"/>
    </inertial>

    <visual>
      <origin xyz="0 0 0" rpy="${pi/2} 0 0"/>
      <geometry>
        <mesh filename="package://rov_gazebo/models/rov_max/meshes/t200-cw-prop.dae" scale="0.8 0.8 0.8"/>
      </geometry>
      <material name="Green"/>
    </visual>

  </link>

  <joint name="shell_to_right_thrust" type="continuous">
    <parent link="rov_max_shell"/>
    <child link="right_thruster"/>
    <axis xyz="0 0 1"/>
    <origin xyz="-0.12429 -0.075 0" rpy="0 ${pi/2} 0"/>
  </joint>

  <!-- ***************************** -->
  <!-- ******* THRUSTER CENTR ****** -->
  <!-- ***************************** -->
  <link name="center_thruster">
    <origin xyz="0 0 0" rpy="0 0 0"/>

    <inertial>
      <mass value="0.001"/>
      <inertia ixx="0.001" ixy="0.00" ixz="0.00" iyy="0.001" iyz="0.00" izz="0.001"/>
    </inertial>

    <visual>
      <origin xyz="0 0 0" rpy="${-pi/2} 0 0"/>
      <geometry>
        <mesh filename="package://rov_gazebo/models/rov_max/meshes/t200-ccw-prop.dae" scale="0.8 0.8 0.8"/>
      </geometry>
      <material name="Green"/>
    </visual>

  </link>

  <joint name="shell_to_center_thrust" type="continuous">
    <parent link="rov_max_shell"/>
    <child link="center_thruster"/>
    <axis xyz="0 0 1"/>
    <origin xyz="-0.175 -0.0 0" rpy="0 0 0"/>
  </joint>

</robot>